<?xml version="1.0" ?>
<!-- =================================================================================== -->
<!-- |    This document was autogenerated by xacro from /home/devansh/MACS/src/Turntable_ROS2_Driver/turntable_description/urdf/turntable.urdf.xacro | -->
<!-- |    EDITING THIS FILE BY HAND IS NOT RECOMMENDED                                 | -->
<!-- =================================================================================== -->
<robot name="turntable">
  <!--
    NOTE the macro defined in this file is NOT part of the public API of this
          package. Users CANNOT rely on this file being available, or stored in
          this location. Nor can they rely on the existence of the macro.
  -->
  <ros2_control name="TurntableSystem" type="system">
    <hardware>
      <plugin>mock_components/GenericSystem</plugin>
      <param name="mock_sensor_commands">true</param>
      <param name="state_following_offset">0.0</param>
      <param name="calculate_dynamics">true</param>
    </hardware>
    <joint name="disc_joint">
      <command_interface name="position"/>
      <state_interface name="position">
        <param name="initial_value">0</param>
      </state_interface>
      <state_interface name="velocity"/>
    </joint>
    <gpio name="speed_scaling">
      <state_interface name="speed_scaling_factor"/>
    </gpio>
  </ros2_control>
  <link name="world"/>
  <!-- Define the turntable name -->
  <!-- BASE LINK -->
  <link name="base_link"/>
  <!-- BASE LINK INERTIA -->
  <link name="base_link_inertia">
    <visual>
      <origin rpy="0 0 0" xyz="0 0 0"/>
      <geometry>
        <mesh filename="package://turntable_description/meshes/collision/turntable_base.stl"/>
      </geometry>
      <material name="grey">
        <color rgba="0.6 0.6 0.6 1.0"/>
      </material>
    </visual>
    <collision>
      <origin rpy="0 0 0" xyz="0 0 0.047"/>
      <geometry>
        <cylinder length="0.094" radius="0.1400"/>
      </geometry>
    </collision>
    <inertial>
      <origin rpy="0 0 0" xyz="0 0 0.047"/>
      <mass value="1.5"/>
      <inertia ixx="0.00540992" ixy="0.0" ixz="0.0" iyy="0.00540992" iyz="0.0" izz="0.00861084"/>
    </inertial>
  </link>
  <!-- DISC LINK -->
  <link name="disc_link">
    <visual>
      <origin rpy="0 0 0" xyz="0 0 0"/>
      <geometry>
        <mesh filename="package://turntable_description/meshes/collision/turntable_disc.stl"/>
      </geometry>
      <material name="blue">
        <color rgba="0.4 0.6 0.8 1.0"/>
      </material>
    </visual>
    <collision>
      <origin rpy="0 0 0" xyz="0 0 0"/>
      <geometry>
        <cylinder length="0.008" radius="0.1016"/>
      </geometry>
    </collision>
    <inertial>
      <origin rpy="0 0 0" xyz="0 0 0"/>
      <mass value="0.31"/>
      <inertia ixx="0.00054849" ixy="0.0" ixz="0.0" iyy="0.00054849" iyz="0.0" izz="0.00109368"/>
    </inertial>
  </link>
  <!-- Object-Co-Ordinate Frame -->
  <link name="object_frame"/>
  <!-- ROS-Industrial 'base' frame - turntable base coordinates -->
  <link name="turntable_base"/>
  <!-- FIXED JOINT TO WORLD -->
  <joint name="base_joint" type="fixed">
    <parent link="world"/>
    <child link="base_link"/>
    <origin rpy="0 0 0" xyz="0 0 0"/>
  </joint>
  <!-- Coordinate System Alignment Joint -->
  <joint name="base_link-base_link_inertia" type="fixed">
    <parent link="base_link"/>
    <child link="base_link_inertia"/>
    <!-- Coordinate alignment - add rotation here if needed for REP-103 compliance -->
    <origin rpy="0 0 0" xyz="0 0 0"/>
  </joint>
  <!-- REVOLUTE JOINT -->
  <joint name="disc_joint" type="revolute">
    <parent link="base_link_inertia"/>
    <child link="disc_link"/>
    <origin rpy="0 0 0" xyz="0 0 0.1015"/>
    <axis xyz="0 0 1"/>
    <limit effort="150.0" lower="-3.14" upper="3.14" velocity="3.14"/>
  </joint>
  <!-- Object Mounted on Turntable: Standard frame reference on top of the disc_link -->
  <joint name="object_mount" type="fixed">
    <parent link="disc_link"/>
    <child link="object_frame"/>
    <origin rpy="0 0 0" xyz="0 0 0"/>
  </joint>
  <!-- ROS-Industrial Base Frame -->
  <joint name="base_link-turntable_base_joint" type="fixed">
    <origin rpy="0 0 0" xyz="0 0 0"/>
    <parent link="base_link"/>
    <child link="turntable_base"/>
  </joint>
  <transmission name="disc_trans">
    <type>transmission_interface/SimpleTransmission</type>
    <joint name="disc_joint">
      <hardwareInterface></hardwareInterface>
    </joint>
    <actuator name="disc_motor">
      <mechanicalReduction>1</mechanicalReduction>
    </actuator>
  </transmission>
</robot>
